<robot name="partnet_3505b2f9-b7a7-44c2-900c-6ac80b0fcbc8" xmlns:xacro="http://wiki.ros.org/xacro">
	<xacro:property name="scale" value="100" /><link name="base" />
	<link name="link_0">
		<visual name="switch-1">
			<origin xyz="${-0.2850429947919231 / scale} ${0 / scale} ${-0.031202361924061152 / scale}" />
			<geometry>
				<mesh filename="package://switch_description/urdf/100883/textured_objs/original-4.obj" scale="${1 / scale} ${1 / scale} ${1 / scale}" />
			</geometry>
		</visual>
		<collision>
			<origin xyz="${-0.2850429947919231 / scale} ${0 / scale} ${-0.031202361924061152 / scale}" />
			<geometry>
				<mesh filename="package://switch_description/urdf/100883/textured_objs/original-4.obj" scale="${1 / scale} ${1 / scale} ${1 / scale}" />
			</geometry>
		</collision>
	</link>
	<joint name="joint_0" type="revolute">
		<origin xyz="${0.2850429947919231 / scale} ${0 / scale} ${0.031202361924061152 / scale}" />
		<axis xyz="0 1 0" />
		<child link="link_0" />
		<parent link="link_2" />
		<limit lower="0.0" upper="0.33161255787892263" effort="10.0" velocity="0.1" />
	</joint>
	<link name="link_1">
		<visual name="switch-2">
			<origin xyz="${0.2982585020662718 / scale} ${0 / scale} ${-0.031202445219137696 / scale}" />
			<geometry>
				<mesh filename="package://switch_description/urdf/100883/textured_objs/original-5.obj" scale="${1 / scale} ${1 / scale} ${1 / scale}" />
			</geometry>
		</visual>
		<collision>
			<origin xyz="${0.2982585020662718 / scale} ${0 / scale} ${-0.031202445219137696 / scale}" />
			<geometry>
				<mesh filename="package://switch_description/urdf/100883/textured_objs/original-5.obj" scale="${1 / scale} ${1 / scale} ${1 / scale}" />
			</geometry>
		</collision>
	</link>
	<joint name="joint_1" type="revolute">
		<origin xyz="${-0.2982585020662718 / scale} ${0 / scale} ${0.031202445219137696 / scale}" />
		<axis xyz="0 1 0" />
		<child link="link_1" />
		<parent link="link_2" />
		<limit lower="0.0" upper="0.3141592653589793" effort="10.0" velocity="0.1" />
	</joint>
	<link name="link_2">
		<visual name="base_body-3">
			<origin xyz="${0 / scale} ${0 / scale} ${0 / scale}" />
			<geometry>
				<mesh filename="package://switch_description/urdf/100883/textured_objs/original-21.obj" scale="${1 / scale} ${1 / scale} ${1 / scale}" />
			</geometry>
		</visual>
		<visual name="base_body-3">
			<origin xyz="${0 / scale} ${0 / scale} ${0 / scale}" />
			<geometry>
				<mesh filename="package://switch_description/urdf/100883/textured_objs/original-22.obj" scale="${1 / scale} ${1 / scale} ${1 / scale}" />
			</geometry>
		</visual>
		<visual name="base_body-3">
			<origin xyz="${0 / scale} ${0 / scale} ${0 / scale}" />
			<geometry>
				<mesh filename="package://switch_description/urdf/100883/textured_objs/original-26.obj" scale="${1 / scale} ${1 / scale} ${1 / scale}" />
			</geometry>
		</visual>
		<visual name="base_body-3">
			<origin xyz="${0 / scale} ${0 / scale} ${0 / scale}" />
			<geometry>
				<mesh filename="package://switch_description/urdf/100883/textured_objs/original-3.obj" scale="${1 / scale} ${1 / scale} ${1 / scale}" />
			</geometry>
		</visual>
		<visual name="base_body-3">
			<origin xyz="${0 / scale} ${0 / scale} ${0 / scale}" />
			<geometry>
				<mesh filename="package://switch_description/urdf/100883/textured_objs/original-2.obj" scale="${1 / scale} ${1 / scale} ${1 / scale}" />
			</geometry>
		</visual>
		<visual name="base_body-3">
			<origin xyz="${0 / scale} ${0 / scale} ${0 / scale}" />
			<geometry>
				<mesh filename="package://switch_description/urdf/100883/textured_objs/original-16.obj" scale="${1 / scale} ${1 / scale} ${1 / scale}" />
			</geometry>
		</visual>
		<visual name="base_body-3">
			<origin xyz="${0 / scale} ${0 / scale} ${0 / scale}" />
			<geometry>
				<mesh filename="package://switch_description/urdf/100883/textured_objs/original-8.obj" scale="${1 / scale} ${1 / scale} ${1 / scale}" />
			</geometry>
		</visual>
		<visual name="base_body-3">
			<origin xyz="${0 / scale} ${0 / scale} ${0 / scale}" />
			<geometry>
				<mesh filename="package://switch_description/urdf/100883/textured_objs/original-13.obj" scale="${1 / scale} ${1 / scale} ${1 / scale}" />
			</geometry>
		</visual>
		<visual name="base_body-3">
			<origin xyz="${0 / scale} ${0 / scale} ${0 / scale}" />
			<geometry>
				<mesh filename="package://switch_description/urdf/100883/textured_objs/original-9.obj" scale="${1 / scale} ${1 / scale} ${1 / scale}" />
			</geometry>
		</visual>
		<visual name="base_body-3">
			<origin xyz="${0 / scale} ${0 / scale} ${0 / scale}" />
			<geometry>
				<mesh filename="package://switch_description/urdf/100883/textured_objs/original-27.obj" scale="${1 / scale} ${1 / scale} ${1 / scale}" />
			</geometry>
		</visual>
		<visual name="base_body-3">
			<origin xyz="${0 / scale} ${0 / scale} ${0 / scale}" />
			<geometry>
				<mesh filename="package://switch_description/urdf/100883/textured_objs/original-15.obj" scale="${1 / scale} ${1 / scale} ${1 / scale}" />
			</geometry>
		</visual>
		<visual name="base_body-3">
			<origin xyz="${0 / scale} ${0 / scale} ${0 / scale}" />
			<geometry>
				<mesh filename="package://switch_description/urdf/100883/textured_objs/original-23.obj" scale="${1 / scale} ${1 / scale} ${1 / scale}" />
			</geometry>
		</visual>
		<visual name="base_body-3">
			<origin xyz="${0 / scale} ${0 / scale} ${0 / scale}" />
			<geometry>
				<mesh filename="package://switch_description/urdf/100883/textured_objs/original-11.obj" scale="${1 / scale} ${1 / scale} ${1 / scale}" />
			</geometry>
		</visual>
		<visual name="base_body-3">
			<origin xyz="${0 / scale} ${0 / scale} ${0 / scale}" />
			<geometry>
				<mesh filename="package://switch_description/urdf/100883/textured_objs/original-18.obj" scale="${1 / scale} ${1 / scale} ${1 / scale}" />
			</geometry>
		</visual>
		<visual name="base_body-3">
			<origin xyz="${0 / scale} ${0 / scale} ${0 / scale}" />
			<geometry>
				<mesh filename="package://switch_description/urdf/100883/textured_objs/original-25.obj" scale="${1 / scale} ${1 / scale} ${1 / scale}" />
			</geometry>
		</visual>
		<visual name="base_body-3">
			<origin xyz="${0 / scale} ${0 / scale} ${0 / scale}" />
			<geometry>
				<mesh filename="package://switch_description/urdf/100883/textured_objs/original-17.obj" scale="${1 / scale} ${1 / scale} ${1 / scale}" />
			</geometry>
		</visual>
		<visual name="base_body-3">
			<origin xyz="${0 / scale} ${0 / scale} ${0 / scale}" />
			<geometry>
				<mesh filename="package://switch_description/urdf/100883/textured_objs/original-12.obj" scale="${1 / scale} ${1 / scale} ${1 / scale}" />
			</geometry>
		</visual>
		<visual name="base_body-3">
			<origin xyz="${0 / scale} ${0 / scale} ${0 / scale}" />
			<geometry>
				<mesh filename="package://switch_description/urdf/100883/textured_objs/original-24.obj" scale="${1 / scale} ${1 / scale} ${1 / scale}" />
			</geometry>
		</visual>
		<visual name="base_body-3">
			<origin xyz="${0 / scale} ${0 / scale} ${0 / scale}" />
			<geometry>
				<mesh filename="package://switch_description/urdf/100883/textured_objs/original-20.obj" scale="${1 / scale} ${1 / scale} ${1 / scale}" />
			</geometry>
		</visual>
		<visual name="base_body-3">
			<origin xyz="${0 / scale} ${0 / scale} ${0 / scale}" />
			<geometry>
				<mesh filename="package://switch_description/urdf/100883/textured_objs/original-7.obj" scale="${1 / scale} ${1 / scale} ${1 / scale}" />
			</geometry>
		</visual>
		<visual name="base_body-3">
			<origin xyz="${0 / scale} ${0 / scale} ${0 / scale}" />
			<geometry>
				<mesh filename="package://switch_description/urdf/100883/textured_objs/original-1.obj" scale="${1 / scale} ${1 / scale} ${1 / scale}" />
			</geometry>
		</visual>
		<visual name="base_body-3">
			<origin xyz="${0 / scale} ${0 / scale} ${0 / scale}" />
			<geometry>
				<mesh filename="package://switch_description/urdf/100883/textured_objs/original-10.obj" scale="${1 / scale} ${1 / scale} ${1 / scale}" />
			</geometry>
		</visual>
		<visual name="base_body-3">
			<origin xyz="${0 / scale} ${0 / scale} ${0 / scale}" />
			<geometry>
				<mesh filename="package://switch_description/urdf/100883/textured_objs/original-14.obj" scale="${1 / scale} ${1 / scale} ${1 / scale}" />
			</geometry>
		</visual>
		<visual name="base_body-3">
			<origin xyz="${0 / scale} ${0 / scale} ${0 / scale}" />
			<geometry>
				<mesh filename="package://switch_description/urdf/100883/textured_objs/original-19.obj" scale="${1 / scale} ${1 / scale} ${1 / scale}" />
			</geometry>
		</visual>
		<collision>
			<origin xyz="${0 / scale} ${0 / scale} ${0 / scale}" />
			<geometry>
				<mesh filename="package://switch_description/urdf/100883/textured_objs/original-21.obj" scale="${1 / scale} ${1 / scale} ${1 / scale}" />
			</geometry>
		</collision>
		<collision>
			<origin xyz="${0 / scale} ${0 / scale} ${0 / scale}" />
			<geometry>
				<mesh filename="package://switch_description/urdf/100883/textured_objs/original-22.obj" scale="${1 / scale} ${1 / scale} ${1 / scale}" />
			</geometry>
		</collision>
		<collision>
			<origin xyz="${0 / scale} ${0 / scale} ${0 / scale}" />
			<geometry>
				<mesh filename="package://switch_description/urdf/100883/textured_objs/original-26.obj" scale="${1 / scale} ${1 / scale} ${1 / scale}" />
			</geometry>
		</collision>
		<collision>
			<origin xyz="${0 / scale} ${0 / scale} ${0 / scale}" />
			<geometry>
				<mesh filename="package://switch_description/urdf/100883/textured_objs/original-3.obj" scale="${1 / scale} ${1 / scale} ${1 / scale}" />
			</geometry>
		</collision>
		<collision>
			<origin xyz="${0 / scale} ${0 / scale} ${0 / scale}" />
			<geometry>
				<mesh filename="package://switch_description/urdf/100883/textured_objs/original-2.obj" scale="${1 / scale} ${1 / scale} ${1 / scale}" />
			</geometry>
		</collision>
		<collision>
			<origin xyz="${0 / scale} ${0 / scale} ${0 / scale}" />
			<geometry>
				<mesh filename="package://switch_description/urdf/100883/textured_objs/original-16.obj" scale="${1 / scale} ${1 / scale} ${1 / scale}" />
			</geometry>
		</collision>
		<collision>
			<origin xyz="${0 / scale} ${0 / scale} ${0 / scale}" />
			<geometry>
				<mesh filename="package://switch_description/urdf/100883/textured_objs/original-8.obj" scale="${1 / scale} ${1 / scale} ${1 / scale}" />
			</geometry>
		</collision>
		<collision>
			<origin xyz="${0 / scale} ${0 / scale} ${0 / scale}" />
			<geometry>
				<mesh filename="package://switch_description/urdf/100883/textured_objs/original-13.obj" scale="${1 / scale} ${1 / scale} ${1 / scale}" />
			</geometry>
		</collision>
		<collision>
			<origin xyz="${0 / scale} ${0 / scale} ${0 / scale}" />
			<geometry>
				<mesh filename="package://switch_description/urdf/100883/textured_objs/original-9.obj" scale="${1 / scale} ${1 / scale} ${1 / scale}" />
			</geometry>
		</collision>
		<collision>
			<origin xyz="${0 / scale} ${0 / scale} ${0 / scale}" />
			<geometry>
				<mesh filename="package://switch_description/urdf/100883/textured_objs/original-27.obj" scale="${1 / scale} ${1 / scale} ${1 / scale}" />
			</geometry>
		</collision>
		<collision>
			<origin xyz="${0 / scale} ${0 / scale} ${0 / scale}" />
			<geometry>
				<mesh filename="package://switch_description/urdf/100883/textured_objs/original-15.obj" scale="${1 / scale} ${1 / scale} ${1 / scale}" />
			</geometry>
		</collision>
		<collision>
			<origin xyz="${0 / scale} ${0 / scale} ${0 / scale}" />
			<geometry>
				<mesh filename="package://switch_description/urdf/100883/textured_objs/original-23.obj" scale="${1 / scale} ${1 / scale} ${1 / scale}" />
			</geometry>
		</collision>
		<collision>
			<origin xyz="${0 / scale} ${0 / scale} ${0 / scale}" />
			<geometry>
				<mesh filename="package://switch_description/urdf/100883/textured_objs/original-11.obj" scale="${1 / scale} ${1 / scale} ${1 / scale}" />
			</geometry>
		</collision>
		<collision>
			<origin xyz="${0 / scale} ${0 / scale} ${0 / scale}" />
			<geometry>
				<mesh filename="package://switch_description/urdf/100883/textured_objs/original-18.obj" scale="${1 / scale} ${1 / scale} ${1 / scale}" />
			</geometry>
		</collision>
		<collision>
			<origin xyz="${0 / scale} ${0 / scale} ${0 / scale}" />
			<geometry>
				<mesh filename="package://switch_description/urdf/100883/textured_objs/original-25.obj" scale="${1 / scale} ${1 / scale} ${1 / scale}" />
			</geometry>
		</collision>
		<collision>
			<origin xyz="${0 / scale} ${0 / scale} ${0 / scale}" />
			<geometry>
				<mesh filename="package://switch_description/urdf/100883/textured_objs/original-17.obj" scale="${1 / scale} ${1 / scale} ${1 / scale}" />
			</geometry>
		</collision>
		<collision>
			<origin xyz="${0 / scale} ${0 / scale} ${0 / scale}" />
			<geometry>
				<mesh filename="package://switch_description/urdf/100883/textured_objs/original-12.obj" scale="${1 / scale} ${1 / scale} ${1 / scale}" />
			</geometry>
		</collision>
		<collision>
			<origin xyz="${0 / scale} ${0 / scale} ${0 / scale}" />
			<geometry>
				<mesh filename="package://switch_description/urdf/100883/textured_objs/original-24.obj" scale="${1 / scale} ${1 / scale} ${1 / scale}" />
			</geometry>
		</collision>
		<collision>
			<origin xyz="${0 / scale} ${0 / scale} ${0 / scale}" />
			<geometry>
				<mesh filename="package://switch_description/urdf/100883/textured_objs/original-20.obj" scale="${1 / scale} ${1 / scale} ${1 / scale}" />
			</geometry>
		</collision>
		<collision>
			<origin xyz="${0 / scale} ${0 / scale} ${0 / scale}" />
			<geometry>
				<mesh filename="package://switch_description/urdf/100883/textured_objs/original-7.obj" scale="${1 / scale} ${1 / scale} ${1 / scale}" />
			</geometry>
		</collision>
		<collision>
			<origin xyz="${0 / scale} ${0 / scale} ${0 / scale}" />
			<geometry>
				<mesh filename="package://switch_description/urdf/100883/textured_objs/original-1.obj" scale="${1 / scale} ${1 / scale} ${1 / scale}" />
			</geometry>
		</collision>
		<collision>
			<origin xyz="${0 / scale} ${0 / scale} ${0 / scale}" />
			<geometry>
				<mesh filename="package://switch_description/urdf/100883/textured_objs/original-10.obj" scale="${1 / scale} ${1 / scale} ${1 / scale}" />
			</geometry>
		</collision>
		<collision>
			<origin xyz="${0 / scale} ${0 / scale} ${0 / scale}" />
			<geometry>
				<mesh filename="package://switch_description/urdf/100883/textured_objs/original-14.obj" scale="${1 / scale} ${1 / scale} ${1 / scale}" />
			</geometry>
		</collision>
		<collision>
			<origin xyz="${0 / scale} ${0 / scale} ${0 / scale}" />
			<geometry>
				<mesh filename="package://switch_description/urdf/100883/textured_objs/original-19.obj" scale="${1 / scale} ${1 / scale} ${1 / scale}" />
			</geometry>
		</collision>
	</link>
	<joint name="joint_2" type="fixed">
		<origin rpy="1.570796326794897 0 -1.570796326794897" xyz="${0 / scale} ${0 / scale} ${0 / scale}" />
		<child link="link_2" />
		<parent link="base" />
	</joint>
</robot>
