<robot name="partnet_5a8c4b01d7cdc687243fd6c0bc6255e8" xmlns:xacro="http://wiki.ros.org/xacro">
	<xacro:property name="scale" value="100" /><link name="base" />
	<link name="link_0">
		<visual name="switch-1">
			<origin xyz="${0 / scale} ${-0.02442769136321424 / scale} ${-0.22830663284163158 / scale}" />
			<geometry>
				<mesh filename="package://switch_description/urdf/100907/textured_objs/original-3.obj" scale="${1 / scale} ${1 / scale} ${1 / scale}" />
			</geometry>
		</visual>
		<visual name="switch-1">
			<origin xyz="${0 / scale} ${-0.02442769136321424 / scale} ${-0.22830663284163158 / scale}" />
			<geometry>
				<mesh filename="package://switch_description/urdf/100907/textured_objs/original-2.obj" scale="${1 / scale} ${1 / scale} ${1 / scale}" />
			</geometry>
		</visual>
		<visual name="switch-1">
			<origin xyz="${0 / scale} ${-0.02442769136321424 / scale} ${-0.22830663284163158 / scale}" />
			<geometry>
				<mesh filename="package://switch_description/urdf/100907/textured_objs/original-9.obj" scale="${1 / scale} ${1 / scale} ${1 / scale}" />
			</geometry>
		</visual>
		<visual name="switch-1">
			<origin xyz="${0 / scale} ${-0.02442769136321424 / scale} ${-0.22830663284163158 / scale}" />
			<geometry>
				<mesh filename="package://switch_description/urdf/100907/textured_objs/original-5.obj" scale="${1 / scale} ${1 / scale} ${1 / scale}" />
			</geometry>
		</visual>
		<visual name="switch-1">
			<origin xyz="${0 / scale} ${-0.02442769136321424 / scale} ${-0.22830663284163158 / scale}" />
			<geometry>
				<mesh filename="package://switch_description/urdf/100907/textured_objs/original-6.obj" scale="${1 / scale} ${1 / scale} ${1 / scale}" />
			</geometry>
		</visual>
		<visual name="switch-1">
			<origin xyz="${0 / scale} ${-0.02442769136321424 / scale} ${-0.22830663284163158 / scale}" />
			<geometry>
				<mesh filename="package://switch_description/urdf/100907/textured_objs/original-7.obj" scale="${1 / scale} ${1 / scale} ${1 / scale}" />
			</geometry>
		</visual>
		<collision>
			<origin xyz="${0 / scale} ${-0.02442769136321424 / scale} ${-0.22830663284163158 / scale}" />
			<geometry>
				<mesh filename="package://switch_description/urdf/100907/textured_objs/original-3.obj" scale="${1 / scale} ${1 / scale} ${1 / scale}" />
			</geometry>
		</collision>
		<collision>
			<origin xyz="${0 / scale} ${-0.02442769136321424 / scale} ${-0.22830663284163158 / scale}" />
			<geometry>
				<mesh filename="package://switch_description/urdf/100907/textured_objs/original-2.obj" scale="${1 / scale} ${1 / scale} ${1 / scale}" />
			</geometry>
		</collision>
		<collision>
			<origin xyz="${0 / scale} ${-0.02442769136321424 / scale} ${-0.22830663284163158 / scale}" />
			<geometry>
				<mesh filename="package://switch_description/urdf/100907/textured_objs/original-9.obj" scale="${1 / scale} ${1 / scale} ${1 / scale}" />
			</geometry>
		</collision>
		<collision>
			<origin xyz="${0 / scale} ${-0.02442769136321424 / scale} ${-0.22830663284163158 / scale}" />
			<geometry>
				<mesh filename="package://switch_description/urdf/100907/textured_objs/original-5.obj" scale="${1 / scale} ${1 / scale} ${1 / scale}" />
			</geometry>
		</collision>
		<collision>
			<origin xyz="${0 / scale} ${-0.02442769136321424 / scale} ${-0.22830663284163158 / scale}" />
			<geometry>
				<mesh filename="package://switch_description/urdf/100907/textured_objs/original-6.obj" scale="${1 / scale} ${1 / scale} ${1 / scale}" />
			</geometry>
		</collision>
		<collision>
			<origin xyz="${0 / scale} ${-0.02442769136321424 / scale} ${-0.22830663284163158 / scale}" />
			<geometry>
				<mesh filename="package://switch_description/urdf/100907/textured_objs/original-7.obj" scale="${1 / scale} ${1 / scale} ${1 / scale}" />
			</geometry>
		</collision>
	</link>
	<joint name="joint_0" type="revolute">
		<origin xyz="${0 / scale} ${0.02442769136321424 / scale} ${0.22830663284163158 / scale}" />
		<axis xyz="1 0 0" />
		<child link="link_0" />
		<parent link="link_1" />
		<limit lower="-0.03141592653589813" upper="0.4146902302738527" effort="10.0" velocity="0.1" />
	</joint>
	<link name="link_1">
		<visual name="base_body-2">
			<origin xyz="${0 / scale} ${0 / scale} ${0 / scale}" />
			<geometry>
				<mesh filename="package://switch_description/urdf/100907/textured_objs/original-8.obj" scale="${1 / scale} ${1 / scale} ${1 / scale}" />
			</geometry>
		</visual>
		<collision>
			<origin xyz="${0 / scale} ${0 / scale} ${0 / scale}" />
			<geometry>
				<mesh filename="package://switch_description/urdf/100907/textured_objs/original-8.obj" scale="${1 / scale} ${1 / scale} ${1 / scale}" />
			</geometry>
		</collision>
	</link>
	<joint name="joint_1" type="fixed">
		<origin rpy="1.570796326794897 0 -1.570796326794897" xyz="${0 / scale} ${0 / scale} ${0 / scale}" />
		<child link="link_1" />
		<parent link="base" />
	</joint>
</robot>
