<robot name="partnet_786cd5cb-3a4a-4f3c-b32d-f932e864e8a0" xmlns:xacro="http://wiki.ros.org/xacro">
	<xacro:property name="scale" value="100" /><link name="base" />
	<link name="link_0">
		<visual name="switch-1">
			<origin xyz="${-0.45839503479137145 / scale} ${-0.026439931318833647 / scale} ${-0.06249735556131575 / scale}" />
			<geometry>
				<mesh filename="package://switch_description/urdf/100919/textured_objs/original-13.obj" scale="${1 / scale} ${1 / scale} ${1 / scale}" />
			</geometry>
		</visual>
		<collision>
			<origin xyz="${-0.45839503479137145 / scale} ${-0.026439931318833647 / scale} ${-0.06249735556131575 / scale}" />
			<geometry>
				<mesh filename="package://switch_description/urdf/100919/textured_objs/original-13.obj" scale="${1 / scale} ${1 / scale} ${1 / scale}" />
			</geometry>
		</collision>
	</link>
	<joint name="joint_0" type="revolute">
		<origin xyz="${0.45839503479137145 / scale} ${0.026439931318833647 / scale} ${0.06249735556131575 / scale}" />
		<axis xyz="1 0 0" />
		<child link="link_0" />
		<parent link="link_2" />
		<limit lower="0.0" upper="0.3895574890451344" effort="10.0" velocity="0.1" />
	</joint>
	<link name="link_1">
		<visual name="switch-2">
			<origin xyz="${0.18806524263611246 / scale} ${0.2549862866813132 / scale} ${-0.059230504779927085 / scale}" />
			<geometry>
				<mesh filename="package://switch_description/urdf/100919/textured_objs/original-16.obj" scale="${1 / scale} ${1 / scale} ${1 / scale}" />
			</geometry>
		</visual>
		<collision>
			<origin xyz="${0.18806524263611246 / scale} ${0.2549862866813132 / scale} ${-0.059230504779927085 / scale}" />
			<geometry>
				<mesh filename="package://switch_description/urdf/100919/textured_objs/original-16.obj" scale="${1 / scale} ${1 / scale} ${1 / scale}" />
			</geometry>
		</collision>
	</link>
	<joint name="joint_1" type="revolute">
		<origin xyz="${-0.18806524263611246 / scale} ${-0.2549862866813132 / scale} ${0.059230504779927085 / scale}" />
		<axis xyz="1 0 0" />
		<child link="link_1" />
		<parent link="link_2" />
		<limit lower="0.0" upper="0.3895574890451344" effort="10.0" velocity="0.1" />
	</joint>
	<link name="link_2">
		<visual name="base_body-3">
			<origin xyz="${0 / scale} ${0 / scale} ${0 / scale}" />
			<geometry>
				<mesh filename="package://switch_description/urdf/100919/textured_objs/original-4.obj" scale="${1 / scale} ${1 / scale} ${1 / scale}" />
			</geometry>
		</visual>
		<visual name="base_body-3">
			<origin xyz="${0 / scale} ${0 / scale} ${0 / scale}" />
			<geometry>
				<mesh filename="package://switch_description/urdf/100919/textured_objs/original-3.obj" scale="${1 / scale} ${1 / scale} ${1 / scale}" />
			</geometry>
		</visual>
		<visual name="base_body-3">
			<origin xyz="${0 / scale} ${0 / scale} ${0 / scale}" />
			<geometry>
				<mesh filename="package://switch_description/urdf/100919/textured_objs/original-2.obj" scale="${1 / scale} ${1 / scale} ${1 / scale}" />
			</geometry>
		</visual>
		<visual name="base_body-3">
			<origin xyz="${0 / scale} ${0 / scale} ${0 / scale}" />
			<geometry>
				<mesh filename="package://switch_description/urdf/100919/textured_objs/original-8.obj" scale="${1 / scale} ${1 / scale} ${1 / scale}" />
			</geometry>
		</visual>
		<visual name="base_body-3">
			<origin xyz="${0 / scale} ${0 / scale} ${0 / scale}" />
			<geometry>
				<mesh filename="package://switch_description/urdf/100919/textured_objs/original-9.obj" scale="${1 / scale} ${1 / scale} ${1 / scale}" />
			</geometry>
		</visual>
		<visual name="base_body-3">
			<origin xyz="${0 / scale} ${0 / scale} ${0 / scale}" />
			<geometry>
				<mesh filename="package://switch_description/urdf/100919/textured_objs/original-5.obj" scale="${1 / scale} ${1 / scale} ${1 / scale}" />
			</geometry>
		</visual>
		<visual name="base_body-3">
			<origin xyz="${0 / scale} ${0 / scale} ${0 / scale}" />
			<geometry>
				<mesh filename="package://switch_description/urdf/100919/textured_objs/original-6.obj" scale="${1 / scale} ${1 / scale} ${1 / scale}" />
			</geometry>
		</visual>
		<visual name="base_body-3">
			<origin xyz="${0 / scale} ${0 / scale} ${0 / scale}" />
			<geometry>
				<mesh filename="package://switch_description/urdf/100919/textured_objs/original-11.obj" scale="${1 / scale} ${1 / scale} ${1 / scale}" />
			</geometry>
		</visual>
		<visual name="base_body-3">
			<origin xyz="${0 / scale} ${0 / scale} ${0 / scale}" />
			<geometry>
				<mesh filename="package://switch_description/urdf/100919/textured_objs/original-17.obj" scale="${1 / scale} ${1 / scale} ${1 / scale}" />
			</geometry>
		</visual>
		<visual name="base_body-3">
			<origin xyz="${0 / scale} ${0 / scale} ${0 / scale}" />
			<geometry>
				<mesh filename="package://switch_description/urdf/100919/textured_objs/original-7.obj" scale="${1 / scale} ${1 / scale} ${1 / scale}" />
			</geometry>
		</visual>
		<visual name="base_body-3">
			<origin xyz="${0 / scale} ${0 / scale} ${0 / scale}" />
			<geometry>
				<mesh filename="package://switch_description/urdf/100919/textured_objs/original-1.obj" scale="${1 / scale} ${1 / scale} ${1 / scale}" />
			</geometry>
		</visual>
		<visual name="base_body-3">
			<origin xyz="${0 / scale} ${0 / scale} ${0 / scale}" />
			<geometry>
				<mesh filename="package://switch_description/urdf/100919/textured_objs/original-10.obj" scale="${1 / scale} ${1 / scale} ${1 / scale}" />
			</geometry>
		</visual>
		<visual name="base_body-3">
			<origin xyz="${0 / scale} ${0 / scale} ${0 / scale}" />
			<geometry>
				<mesh filename="package://switch_description/urdf/100919/textured_objs/original-14.obj" scale="${1 / scale} ${1 / scale} ${1 / scale}" />
			</geometry>
		</visual>
		<collision>
			<origin xyz="${0 / scale} ${0 / scale} ${0 / scale}" />
			<geometry>
				<mesh filename="package://switch_description/urdf/100919/textured_objs/original-4.obj" scale="${1 / scale} ${1 / scale} ${1 / scale}" />
			</geometry>
		</collision>
		<collision>
			<origin xyz="${0 / scale} ${0 / scale} ${0 / scale}" />
			<geometry>
				<mesh filename="package://switch_description/urdf/100919/textured_objs/original-3.obj" scale="${1 / scale} ${1 / scale} ${1 / scale}" />
			</geometry>
		</collision>
		<collision>
			<origin xyz="${0 / scale} ${0 / scale} ${0 / scale}" />
			<geometry>
				<mesh filename="package://switch_description/urdf/100919/textured_objs/original-2.obj" scale="${1 / scale} ${1 / scale} ${1 / scale}" />
			</geometry>
		</collision>
		<collision>
			<origin xyz="${0 / scale} ${0 / scale} ${0 / scale}" />
			<geometry>
				<mesh filename="package://switch_description/urdf/100919/textured_objs/original-8.obj" scale="${1 / scale} ${1 / scale} ${1 / scale}" />
			</geometry>
		</collision>
		<collision>
			<origin xyz="${0 / scale} ${0 / scale} ${0 / scale}" />
			<geometry>
				<mesh filename="package://switch_description/urdf/100919/textured_objs/original-9.obj" scale="${1 / scale} ${1 / scale} ${1 / scale}" />
			</geometry>
		</collision>
		<collision>
			<origin xyz="${0 / scale} ${0 / scale} ${0 / scale}" />
			<geometry>
				<mesh filename="package://switch_description/urdf/100919/textured_objs/original-5.obj" scale="${1 / scale} ${1 / scale} ${1 / scale}" />
			</geometry>
		</collision>
		<collision>
			<origin xyz="${0 / scale} ${0 / scale} ${0 / scale}" />
			<geometry>
				<mesh filename="package://switch_description/urdf/100919/textured_objs/original-6.obj" scale="${1 / scale} ${1 / scale} ${1 / scale}" />
			</geometry>
		</collision>
		<collision>
			<origin xyz="${0 / scale} ${0 / scale} ${0 / scale}" />
			<geometry>
				<mesh filename="package://switch_description/urdf/100919/textured_objs/original-11.obj" scale="${1 / scale} ${1 / scale} ${1 / scale}" />
			</geometry>
		</collision>
		<collision>
			<origin xyz="${0 / scale} ${0 / scale} ${0 / scale}" />
			<geometry>
				<mesh filename="package://switch_description/urdf/100919/textured_objs/original-17.obj" scale="${1 / scale} ${1 / scale} ${1 / scale}" />
			</geometry>
		</collision>
		<collision>
			<origin xyz="${0 / scale} ${0 / scale} ${0 / scale}" />
			<geometry>
				<mesh filename="package://switch_description/urdf/100919/textured_objs/original-7.obj" scale="${1 / scale} ${1 / scale} ${1 / scale}" />
			</geometry>
		</collision>
		<collision>
			<origin xyz="${0 / scale} ${0 / scale} ${0 / scale}" />
			<geometry>
				<mesh filename="package://switch_description/urdf/100919/textured_objs/original-1.obj" scale="${1 / scale} ${1 / scale} ${1 / scale}" />
			</geometry>
		</collision>
		<collision>
			<origin xyz="${0 / scale} ${0 / scale} ${0 / scale}" />
			<geometry>
				<mesh filename="package://switch_description/urdf/100919/textured_objs/original-10.obj" scale="${1 / scale} ${1 / scale} ${1 / scale}" />
			</geometry>
		</collision>
		<collision>
			<origin xyz="${0 / scale} ${0 / scale} ${0 / scale}" />
			<geometry>
				<mesh filename="package://switch_description/urdf/100919/textured_objs/original-14.obj" scale="${1 / scale} ${1 / scale} ${1 / scale}" />
			</geometry>
		</collision>
	</link>
	<joint name="joint_2" type="fixed">
		<origin rpy="1.570796326794897 0 -1.570796326794897" xyz="${0 / scale} ${0 / scale} ${0 / scale}" />
		<child link="link_2" />
		<parent link="base" />
	</joint>
</robot>
