<robot name="partnet_bdf19a60512b5112aec118775e1a3eb4" xmlns:xacro="http://wiki.ros.org/xacro">
	<xacro:property name="scale" value="100" /><link name="base" />
	<link name="link_0">
		<visual name="outside_frame-12">
			<origin xyz="${0 / scale} ${0 / scale} ${0 / scale}" />
			<geometry>
				<mesh filename="package://switch_description/urdf/8903/textured_objs/original-29.obj" scale="${1 / scale} ${1 / scale} ${1 / scale}" />
			</geometry>
		</visual>
		<collision>
			<origin xyz="${0 / scale} ${0 / scale} ${0 / scale}" />
			<geometry>
				<mesh filename="package://switch_description/urdf/8903/textured_objs/original-29.obj" scale="${1 / scale} ${1 / scale} ${1 / scale}" />
			</geometry>
		</collision>
	</link>
	<joint name="joint_0" type="fixed">
		<origin rpy="1.570796326794897 0 -1.570796326794897" xyz="${0 / scale} ${0 / scale} ${0 / scale}" />
		<child link="link_0" />
		<parent link="base" />
	</joint>
	<link name="link_1">
		<visual name="movable_part-10">
			<origin xyz="${0.2718480576000603 / scale} ${-0.14707143841511927 / scale} ${-0.07412800192832969 / scale}" />
			<geometry>
				<mesh filename="package://switch_description/urdf/8903/textured_objs/original-24.obj" scale="${1 / scale} ${1 / scale} ${1 / scale}" />
			</geometry>
		</visual>
		<visual name="movable_part-8">
			<origin xyz="${0.2718480576000603 / scale} ${-0.14707143841511927 / scale} ${-0.07412800192832969 / scale}" />
			<geometry>
				<mesh filename="package://switch_description/urdf/8903/textured_objs/original-27.obj" scale="${1 / scale} ${1 / scale} ${1 / scale}" />
			</geometry>
		</visual>
		<collision>
			<origin xyz="${0.2718480576000603 / scale} ${-0.14707143841511927 / scale} ${-0.07412800192832969 / scale}" />
			<geometry>
				<mesh filename="package://switch_description/urdf/8903/textured_objs/original-24.obj" scale="${1 / scale} ${1 / scale} ${1 / scale}" />
			</geometry>
		</collision>
		<collision>
			<origin xyz="${0.2718480576000603 / scale} ${-0.14707143841511927 / scale} ${-0.07412800192832969 / scale}" />
			<geometry>
				<mesh filename="package://switch_description/urdf/8903/textured_objs/original-27.obj" scale="${1 / scale} ${1 / scale} ${1 / scale}" />
			</geometry>
		</collision>
	</link>
	<joint name="joint_1" type="revolute">
		<origin xyz="${-0.6421963903449441 / scale} ${-0.7487525767254141 / scale} ${0.0723845451324776 / scale}" />
		<axis xyz="0 0 1" />
		<child link="link_1" />
		<parent link="link_2" />
		<limit lower="0.0" upper="1.5707963267948966" effort="10.0" velocity="0.1" />
	</joint>
	<link name="link_2">
		<visual name="surface_board-11">
			<origin xyz="${-0.37034833274488377 / scale} ${-0.8958240151405333 / scale} ${-0.0017434567958520795 / scale}" />
			<geometry>
				<mesh filename="package://switch_description/urdf/8903/textured_objs/original-1.obj" scale="${1 / scale} ${1 / scale} ${1 / scale}" />
			</geometry>
		</visual>
		<visual name="fixed_part-9">
			<origin xyz="${-0.37034833274488377 / scale} ${-0.8958240151405333 / scale} ${-0.0017434567958520795 / scale}" />
			<geometry>
				<mesh filename="package://switch_description/urdf/8903/textured_objs/original-23.obj" scale="${1 / scale} ${1 / scale} ${1 / scale}" />
			</geometry>
		</visual>
		<visual name="fixed_part-7">
			<origin xyz="${-0.37034833274488377 / scale} ${-0.8958240151405333 / scale} ${-0.0017434567958520795 / scale}" />
			<geometry>
				<mesh filename="package://switch_description/urdf/8903/textured_objs/original-26.obj" scale="${1 / scale} ${1 / scale} ${1 / scale}" />
			</geometry>
		</visual>
		<collision>
			<origin xyz="${-0.37034833274488377 / scale} ${-0.8958240151405333 / scale} ${-0.0017434567958520795 / scale}" />
			<geometry>
				<mesh filename="package://switch_description/urdf/8903/textured_objs/original-1.obj" scale="${1 / scale} ${1 / scale} ${1 / scale}" />
			</geometry>
		</collision>
		<collision>
			<origin xyz="${-0.37034833274488377 / scale} ${-0.8958240151405333 / scale} ${-0.0017434567958520795 / scale}" />
			<geometry>
				<mesh filename="package://switch_description/urdf/8903/textured_objs/original-23.obj" scale="${1 / scale} ${1 / scale} ${1 / scale}" />
			</geometry>
		</collision>
		<collision>
			<origin xyz="${-0.37034833274488377 / scale} ${-0.8958240151405333 / scale} ${-0.0017434567958520795 / scale}" />
			<geometry>
				<mesh filename="package://switch_description/urdf/8903/textured_objs/original-26.obj" scale="${1 / scale} ${1 / scale} ${1 / scale}" />
			</geometry>
		</collision>
	</link>
	<joint name="joint_2" type="revolute">
		<origin xyz="${0.37034833274488377 / scale} ${0.8958240151405333 / scale} ${0.0017434567958520795 / scale}" />
		<axis xyz="0 0.9999999999999999 0" />
		<child link="link_2" />
		<parent link="link_0" />
		<limit lower="0.0" upper="1.5707963267948966" effort="10.0" velocity="0.1" />
	</joint>
</robot>
