<robot name="partnet_3f7d636f676850442a60b2309aec10ad" xmlns:xacro="http://wiki.ros.org/xacro">
	<xacro:property name="scale" value="100" /><link name="base" />
	<link name="link_0">
		<visual name="outside_frame-3">
			<origin xyz="${0 / scale} ${0 / scale} ${0 / scale}" />
			<geometry>
				<mesh filename="package://switch_description/urdf/8877/textured_objs/original-2.obj" scale="${1 / scale} ${1 / scale} ${1 / scale}" />
			</geometry>
		</visual>
		<visual name="outside_frame-3">
			<origin xyz="${0 / scale} ${0 / scale} ${0 / scale}" />
			<geometry>
				<mesh filename="package://switch_description/urdf/8877/textured_objs/original-3.obj" scale="${1 / scale} ${1 / scale} ${1 / scale}" />
			</geometry>
		</visual>
		<visual name="outside_frame-3">
			<origin xyz="${0 / scale} ${0 / scale} ${0 / scale}" />
			<geometry>
				<mesh filename="package://switch_description/urdf/8877/textured_objs/new-1.obj" scale="${1 / scale} ${1 / scale} ${1 / scale}" />
			</geometry>
		</visual>
		<collision>
			<origin xyz="${0 / scale} ${0 / scale} ${0 / scale}" />
			<geometry>
				<mesh filename="package://switch_description/urdf/8877/textured_objs/original-2.obj" scale="${1 / scale} ${1 / scale} ${1 / scale}" />
			</geometry>
		</collision>
		<collision>
			<origin xyz="${0 / scale} ${0 / scale} ${0 / scale}" />
			<geometry>
				<mesh filename="package://switch_description/urdf/8877/textured_objs/original-3.obj" scale="${1 / scale} ${1 / scale} ${1 / scale}" />
			</geometry>
		</collision>
		<collision>
			<origin xyz="${0 / scale} ${0 / scale} ${0 / scale}" />
			<geometry>
				<mesh filename="package://switch_description/urdf/8877/textured_objs/new-1.obj" scale="${1 / scale} ${1 / scale} ${1 / scale}" />
			</geometry>
		</collision>
	</link>
	<joint name="joint_0" type="fixed">
		<origin rpy="1.570796326794897 0 -1.570796326794897" xyz="${0 / scale} ${0 / scale} ${0 / scale}" />
		<child link="link_0" />
		<parent link="base" />
	</joint>
	<link name="link_1">
		<visual name="surface_board-9">
			<origin xyz="${0.3229034707136453 / scale} ${0 / scale} ${-0.04352036807686092 / scale}" />
			<geometry>
				<mesh filename="package://switch_description/urdf/8877/textured_objs/new-2.obj" scale="${1 / scale} ${1 / scale} ${1 / scale}" />
			</geometry>
		</visual>
		<collision>
			<origin xyz="${0.3229034707136453 / scale} ${0 / scale} ${-0.04352036807686092 / scale}" />
			<geometry>
				<mesh filename="package://switch_description/urdf/8877/textured_objs/new-2.obj" scale="${1 / scale} ${1 / scale} ${1 / scale}" />
			</geometry>
		</collision>
	</link>
	<joint name="joint_1" type="revolute">
		<origin xyz="${-0.3229034707136453 / scale} ${0 / scale} ${0.04352036807686092 / scale}" />
		<axis xyz="0 1 0" />
		<child link="link_1" />
		<parent link="link_0" />
		<limit lower="-1.5707963267948966" upper="0.0" effort="10.0" velocity="0.1" />
	</joint>
	<link name="link_2">
		<visual name="surface_board-7">
			<origin xyz="${-0.3038980982638896 / scale} ${0 / scale} ${-0.058809246495366126 / scale}" />
			<geometry>
				<mesh filename="package://switch_description/urdf/8877/textured_objs/new-0.obj" scale="${1 / scale} ${1 / scale} ${1 / scale}" />
			</geometry>
		</visual>
		<collision>
			<origin xyz="${-0.3038980982638896 / scale} ${0 / scale} ${-0.058809246495366126 / scale}" />
			<geometry>
				<mesh filename="package://switch_description/urdf/8877/textured_objs/new-0.obj" scale="${1 / scale} ${1 / scale} ${1 / scale}" />
			</geometry>
		</collision>
	</link>
	<joint name="joint_2" type="revolute">
		<origin xyz="${0.3038980982638896 / scale} ${0 / scale} ${0.058809246495366126 / scale}" />
		<axis xyz="0 -1 0" />
		<child link="link_2" />
		<parent link="link_0" />
		<limit lower="-1.5707963267948966" upper="-0.0" effort="10.0" velocity="0.1" />
	</joint>
</robot>
