<robot name="partnet_2df413de74de82d2fcbd07bde5deede4" xmlns:xacro="http://wiki.ros.org/xacro">
	<xacro:property name="scale" value="100" /><link name="base" />
	<link name="link_0">
		<visual name="outside_frame-1">
			<origin xyz="${0 / scale} ${0 / scale} ${0 / scale}" />
			<geometry>
				<mesh filename="package://switch_description/urdf/8897/textured_objs/new-2.obj" scale="${1 / scale} ${1 / scale} ${1 / scale}" />
			</geometry>
		</visual>
		<visual name="outside_frame-1">
			<origin xyz="${0 / scale} ${0 / scale} ${0 / scale}" />
			<geometry>
				<mesh filename="package://switch_description/urdf/8897/textured_objs/original-1.obj" scale="${1 / scale} ${1 / scale} ${1 / scale}" />
			</geometry>
		</visual>
		<visual name="outside_frame-1">
			<origin xyz="${0 / scale} ${0 / scale} ${0 / scale}" />
			<geometry>
				<mesh filename="package://switch_description/urdf/8897/textured_objs/new-5.obj" scale="${1 / scale} ${1 / scale} ${1 / scale}" />
			</geometry>
		</visual>
		<collision>
			<origin xyz="${0 / scale} ${0 / scale} ${0 / scale}" />
			<geometry>
				<mesh filename="package://switch_description/urdf/8897/textured_objs/new-2.obj" scale="${1 / scale} ${1 / scale} ${1 / scale}" />
			</geometry>
		</collision>
		<collision>
			<origin xyz="${0 / scale} ${0 / scale} ${0 / scale}" />
			<geometry>
				<mesh filename="package://switch_description/urdf/8897/textured_objs/original-1.obj" scale="${1 / scale} ${1 / scale} ${1 / scale}" />
			</geometry>
		</collision>
		<collision>
			<origin xyz="${0 / scale} ${0 / scale} ${0 / scale}" />
			<geometry>
				<mesh filename="package://switch_description/urdf/8897/textured_objs/new-5.obj" scale="${1 / scale} ${1 / scale} ${1 / scale}" />
			</geometry>
		</collision>
	</link>
	<joint name="joint_0" type="fixed">
		<origin rpy="1.570796326794897 0 -1.570796326794897" xyz="${0 / scale} ${0 / scale} ${0 / scale}" />
		<child link="link_0" />
		<parent link="base" />
	</joint>
	<link name="link_1">
		<visual name="surface_board-12">
			<origin xyz="${0.3432525537649009 / scale} ${-0.828824 / scale} ${0.004683688059689217 / scale}" />
			<geometry>
				<mesh filename="package://switch_description/urdf/8897/textured_objs/new-3.obj" scale="${1 / scale} ${1 / scale} ${1 / scale}" />
			</geometry>
		</visual>
		<visual name="surface_board-12">
			<origin xyz="${0.3432525537649009 / scale} ${-0.828824 / scale} ${0.004683688059689217 / scale}" />
			<geometry>
				<mesh filename="package://switch_description/urdf/8897/textured_objs/new-4.obj" scale="${1 / scale} ${1 / scale} ${1 / scale}" />
			</geometry>
		</visual>
		<visual name="surface_board-12">
			<origin xyz="${0.3432525537649009 / scale} ${-0.828824 / scale} ${0.004683688059689217 / scale}" />
			<geometry>
				<mesh filename="package://switch_description/urdf/8897/textured_objs/new-0.obj" scale="${1 / scale} ${1 / scale} ${1 / scale}" />
			</geometry>
		</visual>
		<visual name="surface_board-12">
			<origin xyz="${0.3432525537649009 / scale} ${-0.828824 / scale} ${0.004683688059689217 / scale}" />
			<geometry>
				<mesh filename="package://switch_description/urdf/8897/textured_objs/new-1.obj" scale="${1 / scale} ${1 / scale} ${1 / scale}" />
			</geometry>
		</visual>
		<visual name="fixed_part-10">
			<origin xyz="${0.3432525537649009 / scale} ${-0.828824 / scale} ${0.004683688059689217 / scale}" />
			<geometry>
				<mesh filename="package://switch_description/urdf/8897/textured_objs/original-17.obj" scale="${1 / scale} ${1 / scale} ${1 / scale}" />
			</geometry>
		</visual>
		<visual name="fixed_part-10">
			<origin xyz="${0.3432525537649009 / scale} ${-0.828824 / scale} ${0.004683688059689217 / scale}" />
			<geometry>
				<mesh filename="package://switch_description/urdf/8897/textured_objs/original-16.obj" scale="${1 / scale} ${1 / scale} ${1 / scale}" />
			</geometry>
		</visual>
		<visual name="fixed_part-10">
			<origin xyz="${0.3432525537649009 / scale} ${-0.828824 / scale} ${0.004683688059689217 / scale}" />
			<geometry>
				<mesh filename="package://switch_description/urdf/8897/textured_objs/original-21.obj" scale="${1 / scale} ${1 / scale} ${1 / scale}" />
			</geometry>
		</visual>
		<visual name="other_leaf-14">
			<origin xyz="${0.3432525537649009 / scale} ${-0.828824 / scale} ${0.004683688059689217 / scale}" />
			<geometry>
				<mesh filename="package://switch_description/urdf/8897/textured_objs/original-20.obj" scale="${1 / scale} ${1 / scale} ${1 / scale}" />
			</geometry>
		</visual>
		<visual name="other_leaf-14">
			<origin xyz="${0.3432525537649009 / scale} ${-0.828824 / scale} ${0.004683688059689217 / scale}" />
			<geometry>
				<mesh filename="package://switch_description/urdf/8897/textured_objs/original-22.obj" scale="${1 / scale} ${1 / scale} ${1 / scale}" />
			</geometry>
		</visual>
		<visual name="fixed_part-8">
			<origin xyz="${0.3432525537649009 / scale} ${-0.828824 / scale} ${0.004683688059689217 / scale}" />
			<geometry>
				<mesh filename="package://switch_description/urdf/8897/textured_objs/original-6.obj" scale="${1 / scale} ${1 / scale} ${1 / scale}" />
			</geometry>
		</visual>
		<visual name="fixed_part-8">
			<origin xyz="${0.3432525537649009 / scale} ${-0.828824 / scale} ${0.004683688059689217 / scale}" />
			<geometry>
				<mesh filename="package://switch_description/urdf/8897/textured_objs/original-5.obj" scale="${1 / scale} ${1 / scale} ${1 / scale}" />
			</geometry>
		</visual>
		<visual name="fixed_part-8">
			<origin xyz="${0.3432525537649009 / scale} ${-0.828824 / scale} ${0.004683688059689217 / scale}" />
			<geometry>
				<mesh filename="package://switch_description/urdf/8897/textured_objs/original-10.obj" scale="${1 / scale} ${1 / scale} ${1 / scale}" />
			</geometry>
		</visual>
		<visual name="other_leaf-16">
			<origin xyz="${0.3432525537649009 / scale} ${-0.828824 / scale} ${0.004683688059689217 / scale}" />
			<geometry>
				<mesh filename="package://switch_description/urdf/8897/textured_objs/original-11.obj" scale="${1 / scale} ${1 / scale} ${1 / scale}" />
			</geometry>
		</visual>
		<visual name="other_leaf-16">
			<origin xyz="${0.3432525537649009 / scale} ${-0.828824 / scale} ${0.004683688059689217 / scale}" />
			<geometry>
				<mesh filename="package://switch_description/urdf/8897/textured_objs/original-9.obj" scale="${1 / scale} ${1 / scale} ${1 / scale}" />
			</geometry>
		</visual>
		<collision>
			<origin xyz="${0.3432525537649009 / scale} ${-0.828824 / scale} ${0.004683688059689217 / scale}" />
			<geometry>
				<mesh filename="package://switch_description/urdf/8897/textured_objs/new-3.obj" scale="${1 / scale} ${1 / scale} ${1 / scale}" />
			</geometry>
		</collision>
		<collision>
			<origin xyz="${0.3432525537649009 / scale} ${-0.828824 / scale} ${0.004683688059689217 / scale}" />
			<geometry>
				<mesh filename="package://switch_description/urdf/8897/textured_objs/new-4.obj" scale="${1 / scale} ${1 / scale} ${1 / scale}" />
			</geometry>
		</collision>
		<collision>
			<origin xyz="${0.3432525537649009 / scale} ${-0.828824 / scale} ${0.004683688059689217 / scale}" />
			<geometry>
				<mesh filename="package://switch_description/urdf/8897/textured_objs/new-0.obj" scale="${1 / scale} ${1 / scale} ${1 / scale}" />
			</geometry>
		</collision>
		<collision>
			<origin xyz="${0.3432525537649009 / scale} ${-0.828824 / scale} ${0.004683688059689217 / scale}" />
			<geometry>
				<mesh filename="package://switch_description/urdf/8897/textured_objs/new-1.obj" scale="${1 / scale} ${1 / scale} ${1 / scale}" />
			</geometry>
		</collision>
		<collision>
			<origin xyz="${0.3432525537649009 / scale} ${-0.828824 / scale} ${0.004683688059689217 / scale}" />
			<geometry>
				<mesh filename="package://switch_description/urdf/8897/textured_objs/original-17.obj" scale="${1 / scale} ${1 / scale} ${1 / scale}" />
			</geometry>
		</collision>
		<collision>
			<origin xyz="${0.3432525537649009 / scale} ${-0.828824 / scale} ${0.004683688059689217 / scale}" />
			<geometry>
				<mesh filename="package://switch_description/urdf/8897/textured_objs/original-16.obj" scale="${1 / scale} ${1 / scale} ${1 / scale}" />
			</geometry>
		</collision>
		<collision>
			<origin xyz="${0.3432525537649009 / scale} ${-0.828824 / scale} ${0.004683688059689217 / scale}" />
			<geometry>
				<mesh filename="package://switch_description/urdf/8897/textured_objs/original-21.obj" scale="${1 / scale} ${1 / scale} ${1 / scale}" />
			</geometry>
		</collision>
		<collision>
			<origin xyz="${0.3432525537649009 / scale} ${-0.828824 / scale} ${0.004683688059689217 / scale}" />
			<geometry>
				<mesh filename="package://switch_description/urdf/8897/textured_objs/original-20.obj" scale="${1 / scale} ${1 / scale} ${1 / scale}" />
			</geometry>
		</collision>
		<collision>
			<origin xyz="${0.3432525537649009 / scale} ${-0.828824 / scale} ${0.004683688059689217 / scale}" />
			<geometry>
				<mesh filename="package://switch_description/urdf/8897/textured_objs/original-22.obj" scale="${1 / scale} ${1 / scale} ${1 / scale}" />
			</geometry>
		</collision>
		<collision>
			<origin xyz="${0.3432525537649009 / scale} ${-0.828824 / scale} ${0.004683688059689217 / scale}" />
			<geometry>
				<mesh filename="package://switch_description/urdf/8897/textured_objs/original-6.obj" scale="${1 / scale} ${1 / scale} ${1 / scale}" />
			</geometry>
		</collision>
		<collision>
			<origin xyz="${0.3432525537649009 / scale} ${-0.828824 / scale} ${0.004683688059689217 / scale}" />
			<geometry>
				<mesh filename="package://switch_description/urdf/8897/textured_objs/original-5.obj" scale="${1 / scale} ${1 / scale} ${1 / scale}" />
			</geometry>
		</collision>
		<collision>
			<origin xyz="${0.3432525537649009 / scale} ${-0.828824 / scale} ${0.004683688059689217 / scale}" />
			<geometry>
				<mesh filename="package://switch_description/urdf/8897/textured_objs/original-10.obj" scale="${1 / scale} ${1 / scale} ${1 / scale}" />
			</geometry>
		</collision>
		<collision>
			<origin xyz="${0.3432525537649009 / scale} ${-0.828824 / scale} ${0.004683688059689217 / scale}" />
			<geometry>
				<mesh filename="package://switch_description/urdf/8897/textured_objs/original-11.obj" scale="${1 / scale} ${1 / scale} ${1 / scale}" />
			</geometry>
		</collision>
		<collision>
			<origin xyz="${0.3432525537649009 / scale} ${-0.828824 / scale} ${0.004683688059689217 / scale}" />
			<geometry>
				<mesh filename="package://switch_description/urdf/8897/textured_objs/original-9.obj" scale="${1 / scale} ${1 / scale} ${1 / scale}" />
			</geometry>
		</collision>
	</link>
	<joint name="joint_1" type="revolute">
		<origin xyz="${-0.3432525537649009 / scale} ${0.828824 / scale} ${-0.004683688059689217 / scale}" />
		<axis xyz="0 -1 0" />
		<child link="link_1" />
		<parent link="link_0" />
		<limit lower="0.0" upper="1.5707963267948966" effort="10.0" velocity="0.1" />
	</joint>
	<link name="link_2">
		<visual name="movable_part-11">
			<origin xyz="${-0.27102619774442194 / scale} ${0.04494619130548938 / scale} ${-0.053442000000000434 / scale}" />
			<geometry>
				<mesh filename="package://switch_description/urdf/8897/textured_objs/original-19.obj" scale="${1 / scale} ${1 / scale} ${1 / scale}" />
			</geometry>
		</visual>
		<visual name="movable_part-11">
			<origin xyz="${-0.27102619774442194 / scale} ${0.04494619130548938 / scale} ${-0.053442000000000434 / scale}" />
			<geometry>
				<mesh filename="package://switch_description/urdf/8897/textured_objs/original-18.obj" scale="${1 / scale} ${1 / scale} ${1 / scale}" />
			</geometry>
		</visual>
		<visual name="movable_part-9">
			<origin xyz="${-0.27102619774442194 / scale} ${0.04494619130548938 / scale} ${-0.053442000000000434 / scale}" />
			<geometry>
				<mesh filename="package://switch_description/urdf/8897/textured_objs/original-7.obj" scale="${1 / scale} ${1 / scale} ${1 / scale}" />
			</geometry>
		</visual>
		<visual name="movable_part-9">
			<origin xyz="${-0.27102619774442194 / scale} ${0.04494619130548938 / scale} ${-0.053442000000000434 / scale}" />
			<geometry>
				<mesh filename="package://switch_description/urdf/8897/textured_objs/original-8.obj" scale="${1 / scale} ${1 / scale} ${1 / scale}" />
			</geometry>
		</visual>
		<collision>
			<origin xyz="${-0.27102619774442194 / scale} ${0.04494619130548938 / scale} ${-0.053442000000000434 / scale}" />
			<geometry>
				<mesh filename="package://switch_description/urdf/8897/textured_objs/original-19.obj" scale="${1 / scale} ${1 / scale} ${1 / scale}" />
			</geometry>
		</collision>
		<collision>
			<origin xyz="${-0.27102619774442194 / scale} ${0.04494619130548938 / scale} ${-0.053442000000000434 / scale}" />
			<geometry>
				<mesh filename="package://switch_description/urdf/8897/textured_objs/original-18.obj" scale="${1 / scale} ${1 / scale} ${1 / scale}" />
			</geometry>
		</collision>
		<collision>
			<origin xyz="${-0.27102619774442194 / scale} ${0.04494619130548938 / scale} ${-0.053442000000000434 / scale}" />
			<geometry>
				<mesh filename="package://switch_description/urdf/8897/textured_objs/original-7.obj" scale="${1 / scale} ${1 / scale} ${1 / scale}" />
			</geometry>
		</collision>
		<collision>
			<origin xyz="${-0.27102619774442194 / scale} ${0.04494619130548938 / scale} ${-0.053442000000000434 / scale}" />
			<geometry>
				<mesh filename="package://switch_description/urdf/8897/textured_objs/original-8.obj" scale="${1 / scale} ${1 / scale} ${1 / scale}" />
			</geometry>
		</collision>
	</link>
	<joint name="joint_2" type="revolute">
		<origin xyz="${0.6142787515093229 / scale} ${-0.8737701913054894 / scale} ${0.05812568805968965 / scale}" />
		<axis xyz="0 0 1" />
		<child link="link_2" />
		<parent link="link_1" />
		<limit lower="0.0" upper="1.5707963267948966" effort="10.0" velocity="0.1" />
	</joint>
</robot>
