<robot name="partnet_ba4e562c7254a4352042b535f7e0616d" xmlns:xacro="http://wiki.ros.org/xacro">
	<xacro:property name="scale" value="100" /><link name="base" />
	<link name="link_0">
		<visual name="switch-1">
			<origin xyz="${0 / scale} ${-0.001455999999999985 / scale} ${-0.032494 / scale}" />
			<geometry>
				<mesh filename="package://switch_description/urdf/100935/textured_objs/original-2.obj" scale="${1 / scale} ${1 / scale} ${1 / scale}" />
			</geometry>
		</visual>
		<collision>
			<origin xyz="${0 / scale} ${-0.001455999999999985 / scale} ${-0.032494 / scale}" />
			<geometry>
				<mesh filename="package://switch_description/urdf/100935/textured_objs/original-2.obj" scale="${1 / scale} ${1 / scale} ${1 / scale}" />
			</geometry>
		</collision>
	</link>
	<joint name="joint_0" type="revolute">
		<origin xyz="${0 / scale} ${0.001455999999999985 / scale} ${0.032494 / scale}" />
		<axis xyz="1 0 0" />
		<child link="link_0" />
		<parent link="link_3" />
		<limit lower="0.0" upper="0.15707963267948966" effort="10.0" velocity="0.1" />
	</joint>
	<link name="link_1">
		<visual name="switch-2">
			<origin xyz="${0 / scale} ${-0.001455999999999985 / scale} ${-0.032494 / scale}" />
			<geometry>
				<mesh filename="package://switch_description/urdf/100935/textured_objs/original-7.obj" scale="${1 / scale} ${1 / scale} ${1 / scale}" />
			</geometry>
		</visual>
		<visual name="switch-2">
			<origin xyz="${0 / scale} ${-0.001455999999999985 / scale} ${-0.032494 / scale}" />
			<geometry>
				<mesh filename="package://switch_description/urdf/100935/textured_objs/original-6.obj" scale="${1 / scale} ${1 / scale} ${1 / scale}" />
			</geometry>
		</visual>
		<collision>
			<origin xyz="${0 / scale} ${-0.001455999999999985 / scale} ${-0.032494 / scale}" />
			<geometry>
				<mesh filename="package://switch_description/urdf/100935/textured_objs/original-7.obj" scale="${1 / scale} ${1 / scale} ${1 / scale}" />
			</geometry>
		</collision>
		<collision>
			<origin xyz="${0 / scale} ${-0.001455999999999985 / scale} ${-0.032494 / scale}" />
			<geometry>
				<mesh filename="package://switch_description/urdf/100935/textured_objs/original-6.obj" scale="${1 / scale} ${1 / scale} ${1 / scale}" />
			</geometry>
		</collision>
	</link>
	<joint name="joint_1" type="revolute">
		<origin xyz="${0 / scale} ${0.001455999999999985 / scale} ${0.032494 / scale}" />
		<axis xyz="1 0 0" />
		<child link="link_1" />
		<parent link="link_3" />
		<limit lower="0.0" upper="0.15707963267948966" effort="10.0" velocity="0.1" />
	</joint>
	<link name="link_2">
		<visual name="switch-3">
			<origin xyz="${0 / scale} ${-0.001455999999999985 / scale} ${-0.032494 / scale}" />
			<geometry>
				<mesh filename="package://switch_description/urdf/100935/textured_objs/original-3.obj" scale="${1 / scale} ${1 / scale} ${1 / scale}" />
			</geometry>
		</visual>
		<collision>
			<origin xyz="${0 / scale} ${-0.001455999999999985 / scale} ${-0.032494 / scale}" />
			<geometry>
				<mesh filename="package://switch_description/urdf/100935/textured_objs/original-3.obj" scale="${1 / scale} ${1 / scale} ${1 / scale}" />
			</geometry>
		</collision>
	</link>
	<joint name="joint_2" type="revolute">
		<origin xyz="${0 / scale} ${0.001455999999999985 / scale} ${0.032494 / scale}" />
		<axis xyz="1 0 0" />
		<child link="link_2" />
		<parent link="link_3" />
		<limit lower="0.0" upper="0.15707963267948966" effort="10.0" velocity="0.1" />
	</joint>
	<link name="link_3">
		<visual name="base_body-4">
			<origin xyz="${0 / scale} ${0 / scale} ${0 / scale}" />
			<geometry>
				<mesh filename="package://switch_description/urdf/100935/textured_objs/original-8.obj" scale="${1 / scale} ${1 / scale} ${1 / scale}" />
			</geometry>
		</visual>
		<visual name="base_body-4">
			<origin xyz="${0 / scale} ${0 / scale} ${0 / scale}" />
			<geometry>
				<mesh filename="package://switch_description/urdf/100935/textured_objs/original-5.obj" scale="${1 / scale} ${1 / scale} ${1 / scale}" />
			</geometry>
		</visual>
		<collision>
			<origin xyz="${0 / scale} ${0 / scale} ${0 / scale}" />
			<geometry>
				<mesh filename="package://switch_description/urdf/100935/textured_objs/original-8.obj" scale="${1 / scale} ${1 / scale} ${1 / scale}" />
			</geometry>
		</collision>
		<collision>
			<origin xyz="${0 / scale} ${0 / scale} ${0 / scale}" />
			<geometry>
				<mesh filename="package://switch_description/urdf/100935/textured_objs/original-5.obj" scale="${1 / scale} ${1 / scale} ${1 / scale}" />
			</geometry>
		</collision>
	</link>
	<joint name="joint_3" type="fixed">
		<origin rpy="1.570796326794897 0 -1.570796326794897" xyz="${0 / scale} ${0 / scale} ${0 / scale}" />
		<child link="link_3" />
		<parent link="base" />
	</joint>
</robot>
