<robot name="partnet_24ef5084512256551bffd4bc88cc8d80" xmlns:xacro="http://wiki.ros.org/xacro">
	<xacro:property name="scale" value="100" /><link name="base" />
	<link name="link_0">
		<visual name="outside_frame-1">
			<origin xyz="${0 / scale} ${0 / scale} ${0 / scale}" />
			<geometry>
				<mesh filename="package://switch_description/urdf/8893/textured_objs/new-4.obj" scale="${1 / scale} ${1 / scale} ${1 / scale}" />
			</geometry>
		</visual>
		<collision>
			<origin xyz="${0 / scale} ${0 / scale} ${0 / scale}" />
			<geometry>
				<mesh filename="package://switch_description/urdf/8893/textured_objs/new-4.obj" scale="${1 / scale} ${1 / scale} ${1 / scale}" />
			</geometry>
		</collision>
	</link>
	<joint name="joint_0" type="fixed">
		<origin rpy="1.570796326794897 0 -1.570796326794897" xyz="${0 / scale} ${0 / scale} ${0 / scale}" />
		<child link="link_0" />
		<parent link="base" />
	</joint>
	<link name="link_1">
		<visual name="movable_part-6">
			<origin xyz="${-0.2993128347862915 / scale} ${0.01659942510257406 / scale} ${0.014336999999999378 / scale}" />
			<geometry>
				<mesh filename="package://switch_description/urdf/8893/textured_objs/original-2.obj" scale="${1 / scale} ${1 / scale} ${1 / scale}" />
			</geometry>
		</visual>
		<collision>
			<origin xyz="${-0.2993128347862915 / scale} ${0.01659942510257406 / scale} ${0.014336999999999378 / scale}" />
			<geometry>
				<mesh filename="package://switch_description/urdf/8893/textured_objs/original-2.obj" scale="${1 / scale} ${1 / scale} ${1 / scale}" />
			</geometry>
		</collision>
	</link>
	<joint name="joint_1" type="revolute">
		<origin xyz="${0.6663215063128132 / scale} ${-0.8974214251025738 / scale} ${-0.022139757071257815 / scale}" />
		<axis xyz="0 0 1" />
		<child link="link_1" />
		<parent link="link_2" />
		<limit lower="0.0" upper="1.5707963267948966" effort="10.0" velocity="0.1" />
	</joint>
	<link name="link_2">
		<visual name="surface_board-7">
			<origin xyz="${0.3670086715265216 / scale} ${-0.8808219999999998 / scale} ${-0.007802757071258437 / scale}" />
			<geometry>
				<mesh filename="package://switch_description/urdf/8893/textured_objs/new-3.obj" scale="${1 / scale} ${1 / scale} ${1 / scale}" />
			</geometry>
		</visual>
		<visual name="surface_board-7">
			<origin xyz="${0.3670086715265216 / scale} ${-0.8808219999999998 / scale} ${-0.007802757071258437 / scale}" />
			<geometry>
				<mesh filename="package://switch_description/urdf/8893/textured_objs/new-6.obj" scale="${1 / scale} ${1 / scale} ${1 / scale}" />
			</geometry>
		</visual>
		<visual name="glass-8">
			<origin xyz="${0.3670086715265216 / scale} ${-0.8808219999999998 / scale} ${-0.007802757071258437 / scale}" />
			<geometry>
				<mesh filename="package://switch_description/urdf/8893/textured_objs/new-2.obj" scale="${1 / scale} ${1 / scale} ${1 / scale}" />
			</geometry>
		</visual>
		<visual name="glass-8">
			<origin xyz="${0.3670086715265216 / scale} ${-0.8808219999999998 / scale} ${-0.007802757071258437 / scale}" />
			<geometry>
				<mesh filename="package://switch_description/urdf/8893/textured_objs/new-5.obj" scale="${1 / scale} ${1 / scale} ${1 / scale}" />
			</geometry>
		</visual>
		<visual name="fixed_part-5">
			<origin xyz="${0.3670086715265216 / scale} ${-0.8808219999999998 / scale} ${-0.007802757071258437 / scale}" />
			<geometry>
				<mesh filename="package://switch_description/urdf/8893/textured_objs/new-0.obj" scale="${1 / scale} ${1 / scale} ${1 / scale}" />
			</geometry>
		</visual>
		<collision>
			<origin xyz="${0.3670086715265216 / scale} ${-0.8808219999999998 / scale} ${-0.007802757071258437 / scale}" />
			<geometry>
				<mesh filename="package://switch_description/urdf/8893/textured_objs/new-3.obj" scale="${1 / scale} ${1 / scale} ${1 / scale}" />
			</geometry>
		</collision>
		<collision>
			<origin xyz="${0.3670086715265216 / scale} ${-0.8808219999999998 / scale} ${-0.007802757071258437 / scale}" />
			<geometry>
				<mesh filename="package://switch_description/urdf/8893/textured_objs/new-6.obj" scale="${1 / scale} ${1 / scale} ${1 / scale}" />
			</geometry>
		</collision>
		<collision>
			<origin xyz="${0.3670086715265216 / scale} ${-0.8808219999999998 / scale} ${-0.007802757071258437 / scale}" />
			<geometry>
				<mesh filename="package://switch_description/urdf/8893/textured_objs/new-2.obj" scale="${1 / scale} ${1 / scale} ${1 / scale}" />
			</geometry>
		</collision>
		<collision>
			<origin xyz="${0.3670086715265216 / scale} ${-0.8808219999999998 / scale} ${-0.007802757071258437 / scale}" />
			<geometry>
				<mesh filename="package://switch_description/urdf/8893/textured_objs/new-5.obj" scale="${1 / scale} ${1 / scale} ${1 / scale}" />
			</geometry>
		</collision>
		<collision>
			<origin xyz="${0.3670086715265216 / scale} ${-0.8808219999999998 / scale} ${-0.007802757071258437 / scale}" />
			<geometry>
				<mesh filename="package://switch_description/urdf/8893/textured_objs/new-0.obj" scale="${1 / scale} ${1 / scale} ${1 / scale}" />
			</geometry>
		</collision>
	</link>
	<joint name="joint_2" type="revolute">
		<origin xyz="${-0.3670086715265216 / scale} ${0.8808219999999998 / scale} ${0.007802757071258437 / scale}" />
		<axis xyz="0 -1 0" />
		<child link="link_2" />
		<parent link="link_0" />
		<limit lower="0.0" upper="1.5707963267948966" effort="10.0" velocity="0.1" />
	</joint>
</robot>
