<robot name="partnet_bea57a17bab41f97dc3d5b9de4300711" xmlns:xacro="http://wiki.ros.org/xacro">
	<xacro:property name="scale" value="100" /><link name="base" />
	<link name="link_0">
		<visual name="switch-1">
			<origin xyz="${0 / scale} ${-0.0014290000000000136 / scale} ${-0.05 / scale}" />
			<geometry>
				<mesh filename="package://switch_description/urdf/100937/textured_objs/original-2.obj" scale="${1 / scale} ${1 / scale} ${1 / scale}" />
			</geometry>
		</visual>
		<collision>
			<origin xyz="${0 / scale} ${-0.0014290000000000136 / scale} ${-0.05 / scale}" />
			<geometry>
				<mesh filename="package://switch_description/urdf/100937/textured_objs/original-2.obj" scale="${1 / scale} ${1 / scale} ${1 / scale}" />
			</geometry>
		</collision>
	</link>
	<joint name="joint_0" type="revolute">
		<origin xyz="${0 / scale} ${0.0014290000000000136 / scale} ${0.05 / scale}" />
		<axis xyz="1 0 0" />
		<child link="link_0" />
		<parent link="link_1" />
		<limit lower="0.0" upper="0.5759586531581288" effort="10.0" velocity="0.1" />
	</joint>
	<link name="link_1">
		<visual name="base_body-2">
			<origin xyz="${0 / scale} ${0 / scale} ${0 / scale}" />
			<geometry>
				<mesh filename="package://switch_description/urdf/100937/textured_objs/original-1.obj" scale="${1 / scale} ${1 / scale} ${1 / scale}" />
			</geometry>
		</visual>
		<collision>
			<origin xyz="${0 / scale} ${0 / scale} ${0 / scale}" />
			<geometry>
				<mesh filename="package://switch_description/urdf/100937/textured_objs/original-1.obj" scale="${1 / scale} ${1 / scale} ${1 / scale}" />
			</geometry>
		</collision>
	</link>
	<joint name="joint_1" type="fixed">
		<origin rpy="1.570796326794897 0 -1.570796326794897" xyz="${0 / scale} ${0 / scale} ${0 / scale}" />
		<child link="link_1" />
		<parent link="base" />
	</joint>
</robot>
