<robot name="partnet_01e2c09a-a2c1-4ce3-aa9c-0b4d293d8eb8" xmlns:xacro="http://wiki.ros.org/xacro">
	<xacro:property name="scale" value="100" /><link name="base" />
	<link name="link_0">
		<visual name="switch-3">
			<origin xyz="${0.2838207236507393 / scale} ${-0.41027900000000006 / scale} ${-0.041660457683965646 / scale}" />
			<geometry>
				<mesh filename="package://switch_description/urdf/100367/textured_objs/original-6.obj" scale="${1 / scale} ${1 / scale} ${1 / scale}" />
			</geometry>
		</visual>
		<visual name="switch-3">
			<origin xyz="${0.2838207236507393 / scale} ${-0.41027900000000006 / scale} ${-0.041660457683965646 / scale}" />
			<geometry>
				<mesh filename="package://switch_description/urdf/100367/textured_objs/original-7.obj" scale="${1 / scale} ${1 / scale} ${1 / scale}" />
			</geometry>
		</visual>
		<collision>
			<origin xyz="${0.2838207236507393 / scale} ${-0.41027900000000006 / scale} ${-0.041660457683965646 / scale}" />
			<geometry>
				<mesh filename="package://switch_description/urdf/100367/textured_objs/original-6.obj" scale="${1 / scale} ${1 / scale} ${1 / scale}" />
			</geometry>
		</collision>
		<collision>
			<origin xyz="${0.2838207236507393 / scale} ${-0.41027900000000006 / scale} ${-0.041660457683965646 / scale}" />
			<geometry>
				<mesh filename="package://switch_description/urdf/100367/textured_objs/original-7.obj" scale="${1 / scale} ${1 / scale} ${1 / scale}" />
			</geometry>
		</collision>
	</link>
	<joint name="joint_0" type="revolute">
		<origin xyz="${-0.2838207236507393 / scale} ${0.41027900000000006 / scale} ${0.041660457683965646 / scale}" />
		<axis xyz="0 1 0" />
		<child link="link_0" />
		<parent link="link_4" />
		<limit lower="0.0" upper="0.3392920065876977" effort="10.0" velocity="0.1" />
	</joint>
	<link name="link_1">
		<visual name="switch-4">
			<origin xyz="${-0.2310836131113914 / scale} ${0.3980400000000004 / scale} ${-0.04455635095940119 / scale}" />
			<geometry>
				<mesh filename="package://switch_description/urdf/100367/textured_objs/original-8.obj" scale="${1 / scale} ${1 / scale} ${1 / scale}" />
			</geometry>
		</visual>
		<collision>
			<origin xyz="${-0.2310836131113914 / scale} ${0.3980400000000004 / scale} ${-0.04455635095940119 / scale}" />
			<geometry>
				<mesh filename="package://switch_description/urdf/100367/textured_objs/original-8.obj" scale="${1 / scale} ${1 / scale} ${1 / scale}" />
			</geometry>
		</collision>
	</link>
	<joint name="joint_1" type="revolute">
		<origin xyz="${0.2310836131113914 / scale} ${-0.3980400000000004 / scale} ${0.04455635095940119 / scale}" />
		<axis xyz="0 1 0" />
		<child link="link_1" />
		<parent link="link_4" />
		<limit lower="0.0" upper="0.25132741228718347" effort="10.0" velocity="0.1" />
	</joint>
	<link name="link_2">
		<visual name="switch-5">
			<origin xyz="${0.3057951825429795 / scale} ${0.39804000000000084 / scale} ${-0.04034042777380281 / scale}" />
			<geometry>
				<mesh filename="package://switch_description/urdf/100367/textured_objs/original-3.obj" scale="${1 / scale} ${1 / scale} ${1 / scale}" />
			</geometry>
		</visual>
		<visual name="switch-5">
			<origin xyz="${0.3057951825429795 / scale} ${0.39804000000000084 / scale} ${-0.04034042777380281 / scale}" />
			<geometry>
				<mesh filename="package://switch_description/urdf/100367/textured_objs/original-4.obj" scale="${1 / scale} ${1 / scale} ${1 / scale}" />
			</geometry>
		</visual>
		<visual name="switch-5">
			<origin xyz="${0.3057951825429795 / scale} ${0.39804000000000084 / scale} ${-0.04034042777380281 / scale}" />
			<geometry>
				<mesh filename="package://switch_description/urdf/100367/textured_objs/original-5.obj" scale="${1 / scale} ${1 / scale} ${1 / scale}" />
			</geometry>
		</visual>
		<collision>
			<origin xyz="${0.3057951825429795 / scale} ${0.39804000000000084 / scale} ${-0.04034042777380281 / scale}" />
			<geometry>
				<mesh filename="package://switch_description/urdf/100367/textured_objs/original-3.obj" scale="${1 / scale} ${1 / scale} ${1 / scale}" />
			</geometry>
		</collision>
		<collision>
			<origin xyz="${0.3057951825429795 / scale} ${0.39804000000000084 / scale} ${-0.04034042777380281 / scale}" />
			<geometry>
				<mesh filename="package://switch_description/urdf/100367/textured_objs/original-4.obj" scale="${1 / scale} ${1 / scale} ${1 / scale}" />
			</geometry>
		</collision>
		<collision>
			<origin xyz="${0.3057951825429795 / scale} ${0.39804000000000084 / scale} ${-0.04034042777380281 / scale}" />
			<geometry>
				<mesh filename="package://switch_description/urdf/100367/textured_objs/original-5.obj" scale="${1 / scale} ${1 / scale} ${1 / scale}" />
			</geometry>
		</collision>
	</link>
	<joint name="joint_2" type="revolute">
		<origin xyz="${-0.3057951825429795 / scale} ${-0.39804000000000084 / scale} ${0.04034042777380281 / scale}" />
		<axis xyz="0 1 0" />
		<child link="link_2" />
		<parent link="link_4" />
		<limit lower="0.0" upper="0.2764601535159018" effort="10.0" velocity="0.1" />
	</joint>
	<link name="link_3">
		<visual name="switch-6">
			<origin xyz="${-0.2310836131113914 / scale} ${0.3980400000000004 / scale} ${-0.04455635095940119 / scale}" />
			<geometry>
				<mesh filename="package://switch_description/urdf/100367/textured_objs/original-14.obj" scale="${1 / scale} ${1 / scale} ${1 / scale}" />
			</geometry>
		</visual>
		<visual name="switch-6">
			<origin xyz="${-0.2310836131113914 / scale} ${0.3980400000000004 / scale} ${-0.04455635095940119 / scale}" />
			<geometry>
				<mesh filename="package://switch_description/urdf/100367/textured_objs/original-9.obj" scale="${1 / scale} ${1 / scale} ${1 / scale}" />
			</geometry>
		</visual>
		<collision>
			<origin xyz="${-0.2310836131113914 / scale} ${0.3980400000000004 / scale} ${-0.04455635095940119 / scale}" />
			<geometry>
				<mesh filename="package://switch_description/urdf/100367/textured_objs/original-14.obj" scale="${1 / scale} ${1 / scale} ${1 / scale}" />
			</geometry>
		</collision>
		<collision>
			<origin xyz="${-0.2310836131113914 / scale} ${0.3980400000000004 / scale} ${-0.04455635095940119 / scale}" />
			<geometry>
				<mesh filename="package://switch_description/urdf/100367/textured_objs/original-9.obj" scale="${1 / scale} ${1 / scale} ${1 / scale}" />
			</geometry>
		</collision>
	</link>
	<joint name="joint_3" type="revolute">
		<origin xyz="${0.2310836131113914 / scale} ${-0.3980400000000004 / scale} ${0.04455635095940119 / scale}" />
		<axis xyz="0 1 0" />
		<child link="link_3" />
		<parent link="link_4" />
		<limit lower="0.0" upper="0.2890265241302609" effort="10.0" velocity="0.1" />
	</joint>
	<link name="link_4">
		<visual name="base_body-7">
			<origin xyz="${0 / scale} ${0 / scale} ${0 / scale}" />
			<geometry>
				<mesh filename="package://switch_description/urdf/100367/textured_objs/original-13.obj" scale="${1 / scale} ${1 / scale} ${1 / scale}" />
			</geometry>
		</visual>
		<visual name="base_body-7">
			<origin xyz="${0 / scale} ${0 / scale} ${0 / scale}" />
			<geometry>
				<mesh filename="package://switch_description/urdf/100367/textured_objs/original-11.obj" scale="${1 / scale} ${1 / scale} ${1 / scale}" />
			</geometry>
		</visual>
		<visual name="base_body-7">
			<origin xyz="${0 / scale} ${0 / scale} ${0 / scale}" />
			<geometry>
				<mesh filename="package://switch_description/urdf/100367/textured_objs/original-12.obj" scale="${1 / scale} ${1 / scale} ${1 / scale}" />
			</geometry>
		</visual>
		<collision>
			<origin xyz="${0 / scale} ${0 / scale} ${0 / scale}" />
			<geometry>
				<mesh filename="package://switch_description/urdf/100367/textured_objs/original-13.obj" scale="${1 / scale} ${1 / scale} ${1 / scale}" />
			</geometry>
		</collision>
		<collision>
			<origin xyz="${0 / scale} ${0 / scale} ${0 / scale}" />
			<geometry>
				<mesh filename="package://switch_description/urdf/100367/textured_objs/original-11.obj" scale="${1 / scale} ${1 / scale} ${1 / scale}" />
			</geometry>
		</collision>
		<collision>
			<origin xyz="${0 / scale} ${0 / scale} ${0 / scale}" />
			<geometry>
				<mesh filename="package://switch_description/urdf/100367/textured_objs/original-12.obj" scale="${1 / scale} ${1 / scale} ${1 / scale}" />
			</geometry>
		</collision>
	</link>
	<joint name="joint_4" type="fixed">
		<origin rpy="1.570796326794897 0 -1.570796326794897" xyz="${0 / scale} ${0 / scale} ${0 / scale}" />
		<child link="link_4" />
		<parent link="base" />
	</joint>
</robot>
